Workbook

Sheet Questions
B1: You are the data analyst of a luxury car dealership. You were assigned with the following tasks:
A2: 1 | B2: What's the most popular car manufacturer? | I2: {=_xlfn.XLOOKUP(MAX(O8:O15),O8:O15,_xlfn.ANCHORARRAY(N8),,0)} -> BMW
A3: 2 | B3: What's the most popular manufacturing country (Refer to "Manufacturing country" sheet)? | I3: {=_xlfn.XLOOKUP(MAX(R8:R12),R8:R12,_xlfn.ANCHORARRAY(Q8))} -> Germany
A4: 3 | B4: What's the least popular color for cars? | I4: {=_xlfn.XLOOKUP(MIN(O20:O24),O20:O24,_xlfn.ANCHORARRAY(N20))} -> Yellow
A5: 4 | B5: What's the average price per owner?
B7: Car | C7: Year | D7: KM Driven | E7: Color | F7: Transimission | G7: Owner | H7: Price (USD) | I7: Manufacturer | J7: Country
B8: BMW 3 Series | C8: 2011 | D8: 205204 | E8: Red | F8: Automatic | G8: 2nd owner | H8: 13241 | I8: {=INDEX(_xlfn.TEXTSPLIT(Table1[[#This Row],[Car]], " "), 1)} -> BMW | J8: =_xlfn.XLOOKUP(Table1[[#This Row],[Manufacturer]],'Manufacturing country'!$A$2:$A$9,'Manufacturing country'!$B$2:$B$9) -> Germany | N8: {=_xlfn.UNIQUE(Table1[Manufacturer])} -> BMW | O8: =COUNTIF(Table1[Manufacturer],N8) -> 7 | Q8: {=_xlfn.UNIQUE(Table1[Country])} -> Germany | R8: =COUNTIF(Table1[Country],Q8) -> 11
B9: BMW X5 | C9: 2012 | D9: 342358 | E9: White | F9: Automatic | G9: 1st owner | H9: 15400 | I9: {=INDEX(_xlfn.TEXTSPLIT(Table1[[#This Row],[Car]], " "), 1)} -> BMW | J9: =_xlfn.XLOOKUP(Table1[[#This Row],[Manufacturer]],'Manufacturing country'!$A$2:$A$9,'Manufacturing country'!$B$2:$B$9) -> Germany | N9: Volvo | O9: =COUNTIF(Table1[Manufacturer],N9) -> 1 | Q9: Sweden | R9: =COUNTIF(Table1[Country],Q9) -> 1
B10: Volvo XC90 | C10: 2013 | D10: 254028 | E10: Black | F10: Manual | G10: 2nd owner | H10: 17452 | I10: {=INDEX(_xlfn.TEXTSPLIT(Table1[[#This Row],[Car]], " "), 1)} -> Volvo | J10: =_xlfn.XLOOKUP(Table1[[#This Row],[Manufacturer]],'Manufacturing country'!$A$2:$A$9,'Manufacturing country'!$B$2:$B$9) -> Sweden | N10: Jaguar | O10: =COUNTIF(Table1[Manufacturer],N10) -> 1 | Q10: UK | R10: =COUNTIF(Table1[Country],Q10) -> 1
B11: Jaguar XF | C11: 2013 | D11: 85320 | E11: White | F11: Automatic | G11: 2nd owner | H11: 18454 | I11: {=INDEX(_xlfn.TEXTSPLIT(Table1[[#This Row],[Car]], " "), 1)} -> Jaguar | J11: =_xlfn.XLOOKUP(Table1[[#This Row],[Manufacturer]],'Manufacturing country'!$A$2:$A$9,'Manufacturing country'!$B$2:$B$9) -> UK | N11: Mercedes | O11: =COUNTIF(Table1[Manufacturer],N11) -> 2 | Q11: Japan | R11: =COUNTIF(Table1[Country],Q11) -> 3
B12: Mercedes S-Class | C12: 2014 | D12: 152985 | E12: Black | F12: Automatic | G12: 2nd owner | H12: 49344 | I12: {=INDEX(_xlfn.TEXTSPLIT(Table1[[#This Row],[Car]], " "), 1)} -> Mercedes | J12: =_xlfn.XLOOKUP(Table1[[#This Row],[Manufacturer]],'Manufacturing country'!$A$2:$A$9,'Manufacturing country'!$B$2:$B$9) -> Germany | N12: Audi | O12: =COUNTIF(Table1[Manufacturer],N12) -> 2 | Q12: USA | R12: =COUNTIF(Table1[Country],Q12) -> 2
B13: Audi Q7 | C13: 2014 | D13: 45832 | E13: White | F13: Manual | G13: 1st owner | H13: 23250 | I13: {=INDEX(_xlfn.TEXTSPLIT(Table1[[#This Row],[Car]], " "), 1)} -> Audi | J13: =_xlfn.XLOOKUP(Table1[[#This Row],[Manufacturer]],'Manufacturing country'!$A$2:$A$9,'Manufacturing country'!$B$2:$B$9) -> Germany | N13: Lexus | O13: =COUNTIF(Table1[Manufacturer],N13) -> 3
B14: Lexus RX350 | C14: 2015 | D14: 130000 | E14: Black | F14: Automatic | G14: 4th owner | H14: 22520 | I14: {=INDEX(_xlfn.TEXTSPLIT(Table1[[#This Row],[Car]], " "), 1)} -> Lexus | J14: =_xlfn.XLOOKUP(Table1[[#This Row],[Manufacturer]],'Manufacturing country'!$A$2:$A$9,'Manufacturing country'!$B$2:$B$9) -> Japan | N14: Tesla | O14: =COUNTIF(Table1[Manufacturer],N14) -> 1
B15: Lexus RX350 | C15: 2016 | D15: 5000 | E15: White | F15: Automatic | G15: 1st owner | H15: 41000 | I15: {=INDEX(_xlfn.TEXTSPLIT(Table1[[#This Row],[Car]], " "), 1)} -> Lexus | J15: =_xlfn.XLOOKUP(Table1[[#This Row],[Manufacturer]],'Manufacturing country'!$A$2:$A$9,'Manufacturing country'!$B$2:$B$9) -> Japan | N15: Cadillac | O15: =COUNTIF(Table1[Manufacturer],N15) -> 1
B16: Audi A3 | C16: 2017 | D16: 130000 | E16: Red | F16: Manual | G16: 2nd owner | H16: 24321 | I16: {=INDEX(_xlfn.TEXTSPLIT(Table1[[#This Row],[Car]], " "), 1)} -> Audi | J16: =_xlfn.XLOOKUP(Table1[[#This Row],[Manufacturer]],'Manufacturing country'!$A$2:$A$9,'Manufacturing country'!$B$2:$B$9) -> Germany
B17: BMW 428i | C17: 2017 | D17: 92450 | E17: Red | F17: Manual | G17: 2nd owner | H17: 35240 | I17: {=INDEX(_xlfn.TEXTSPLIT(Table1[[#This Row],[Car]], " "), 1)} -> BMW | J17: =_xlfn.XLOOKUP(Table1[[#This Row],[Manufacturer]],'Manufacturing country'!$A$2:$A$9,'Manufacturing country'!$B$2:$B$9) -> Germany
B18: BMW X3 | C18: 2018 | D18: 156784 | E18: Blue | F18: Manual | G18: 3rd owner | H18: 37605 | I18: {=INDEX(_xlfn.TEXTSPLIT(Table1[[#This Row],[Car]], " "), 1)} -> BMW | J18: =_xlfn.XLOOKUP(Table1[[#This Row],[Manufacturer]],'Manufacturing country'!$A$2:$A$9,'Manufacturing country'!$B$2:$B$9) -> Germany | Q18: Number 4
B19: Tesla Model 3 | C19: 2018 | D19: 76429 | E19: Yellow | F19: Automatic | G19: 1st owner | H19: 52432 | I19: {=INDEX(_xlfn.TEXTSPLIT(Table1[[#This Row],[Car]], " "), 1)} -> Tesla | J19: =_xlfn.XLOOKUP(Table1[[#This Row],[Manufacturer]],'Manufacturing country'!$A$2:$A$9,'Manufacturing country'!$B$2:$B$9) -> USA | Q19: {=_xlfn.UNIQUE(Table1[Owner])} -> 2nd owner | R19: =AVERAGEIF(Table1[Owner],Q19,Table1[Price (USD)]) -> 30718
B20: Cadillac XT5 | C20: 2018 | D20: 67591 | E20: Blue | F20: Automatic | G20: 2nd owner | H20: 32420 | I20: {=INDEX(_xlfn.TEXTSPLIT(Table1[[#This Row],[Car]], " "), 1)} -> Cadillac | J20: =_xlfn.XLOOKUP(Table1[[#This Row],[Manufacturer]],'Manufacturing country'!$A$2:$A$9,'Manufacturing country'!$B$2:$B$9) -> USA | N20: {=_xlfn.UNIQUE(TRIM(Table1[Color]))} -> Red | O20: {=SUMPRODUCT(--(TRIM(Table1[Color])=N20))} -> 4 | Q20: 1st owner | R20: =AVERAGEIF(Table1[Owner],Q20,Table1[Price (USD)]) -> 36513.667
B21: BMW X5 | C21: 2019 | D21: 52034 | E21: Blue | F21: Automatic | G21: 1st owner | H21: 45000 | I21: {=INDEX(_xlfn.TEXTSPLIT(Table1[[#This Row],[Car]], " "), 1)} -> BMW | J21: =_xlfn.XLOOKUP(Table1[[#This Row],[Manufacturer]],'Manufacturing country'!$A$2:$A$9,'Manufacturing country'!$B$2:$B$9) -> Germany | N21: White | O21: {=SUMPRODUCT(--(TRIM(Table1[Color])=N21))} -> 6 | Q21: 4th owner | R21: =AVERAGEIF(Table1[Owner],Q21,Table1[Price (USD)]) -> 22520
B22: Mercedes S-Class | C22: 2020 | D22: 92450 | E22: Black | F22: Automatic | G22: 3rd owner | H22: 102342 | I22: {=INDEX(_xlfn.TEXTSPLIT(Table1[[#This Row],[Car]], " "), 1)} -> Mercedes | J22: =_xlfn.XLOOKUP(Table1[[#This Row],[Manufacturer]],'Manufacturing country'!$A$2:$A$9,'Manufacturing country'!$B$2:$B$9) -> Germany | N22: Black | O22: {=SUMPRODUCT(--(TRIM(Table1[Color])=N22))} -> 4 | Q22: 3rd owner | R22: =AVERAGEIF(Table1[Owner],Q22,Table1[Price (USD)]) -> 63746.333
B23: BMW X5 | C23: 2020 | D23: 76240 | E23: White | F23: Automatic | G23: 2nd owner | H23: 55272 | I23: {=INDEX(_xlfn.TEXTSPLIT(Table1[[#This Row],[Car]], " "), 1)} -> BMW | J23: =_xlfn.XLOOKUP(Table1[[#This Row],[Manufacturer]],'Manufacturing country'!$A$2:$A$9,'Manufacturing country'!$B$2:$B$9) -> Germany | N23: Blue | O23: {=SUMPRODUCT(--(TRIM(Table1[Color])=N23))} -> 3
B24: Lexus RX350 | C24: 2020 | D24: 98312 | E24: Red | F24: Automatic | G24: 3rd owner | H24: 51292 | I24: {=INDEX(_xlfn.TEXTSPLIT(Table1[[#This Row],[Car]], " "), 1)} -> Lexus | J24: =_xlfn.XLOOKUP(Table1[[#This Row],[Manufacturer]],'Manufacturing country'!$A$2:$A$9,'Manufacturing country'!$B$2:$B$9) -> Japan | N24: Yellow | O24: {=SUMPRODUCT(--(TRIM(Table1[Color])=N24))} -> 1
B25: BMW X3 | C25: 2021 | D25: 17283 | E25: White | F25: Manual | G25: 1st owner | H25: 42000 | I25: {=INDEX(_xlfn.TEXTSPLIT(Table1[[#This Row],[Car]], " "), 1)} -> BMW | J25: =_xlfn.XLOOKUP(Table1[[#This Row],[Manufacturer]],'Manufacturing country'!$A$2:$A$9,'Manufacturing country'!$B$2:$B$9) -> Germany

Sheet Manufacturing country
A1: Company | B1: Country
A2: BMW | B2: Germany
A3: Audi | B3: Germany
A4: Tesla | B4: USA
A5: Jaguar | B5: UK
A6: Mercedes | B6: Germany
A7: Volvo | B7: Sweden
A8: Cadillac | B8: USA
A9: Lexus | B9: Japan

Sheet Solution
B1: Car | C1: Year | D1: KM Driven | E1: Color | F1: Transimission | G1: Owner | H1: Price (USD)
B2: BMW X5 | C2: 2012 | D2: 342358 | E2: White | F2: Automatic | G2: 1st owner | H2: $15400
B3: Audi A3 | C3: 2017 | D3: 130000 | E3: Red | F3: Manual | G3: 2nd owner | H3: $24321
B4: Mercedes S-Class | C4: 2020 | D4: 92450 | E4: Black | F4: Automatic | G4: 3rd owner | H4: $102342
B5: BMW X5 | C5: 2020 | D5: 76240 | E5: White | F5: Automatic | G5: 2nd owner | H5: $55272
B6: BMW X3 | C6: 2021 | D6: 17283 | E6: White | F6: Manual | G6: 1st owner | H6: $42000
B7: Lexus RX350 | C7: 2020 | D7: 98312 | E7: Red | F7: Automatic | G7: 3rd owner | H7: $51292
B8: BMW X3 | C8: 2018 | D8: 156784 | E8: Blue | F8: Manual | G8: 3rd owner | H8: $37605
B9: BMW X5 | C9: 2019 | D9: 52034 | E9: Blue | F9: Automatic | G9: 1st owner | H9: $45000
B10: BMW 3 Series | C10: 2011 | D10: 205204 | E10: Red | F10: Automatic | G10: 2nd owner | H10: $13241
B11: Mercedes S-Class | C11: 2014 | D11: 152985 | E11: Black | F11: Automatic | G11: 2nd owner | H11: $49344
B12: Tesla Model 3 | C12: 2018 | D12: 76429 | E12: Yellow | F12: Automatic | G12: 1st owner | H12: $52432
B13: Volvo XC90 | C13: 2013 | D13: 254028 | E13: Black | F13: Manual | G13: 2nd owner | H13: $17452
... B19: Lexus RX350 | C19: 2015 | D19: 130000 | E19: Black | F19: Automatic | G19: 4th owner | H19: $22520
B21: You are the data analyst of a luxury car dealership. You were assigned with the following tasks:
A22: 1 | B22: What's the most popular car manufacturer?
B24: Answer:
B25: To answer this, we must first extract the manufacturer's name from the "Car" column, as there are manufacturers that have more than one model listed.
B26: To do this, we can add a new column, and apply the LEFT function, combined with a FIND function, to extract only the first word from "Car":
B28: Car | C28: Year | D28: KM Driven | E28: Color | F28: Transimission | G28: Owner | H28: Price (USD) | I28: Manufacturer
B29: BMW X5 | C29: 2012 | D29: 342358 | E29: White | F29: Automatic | G29: 1st owner | H29: $15400 | I29: =LEFT(B29,FIND(" ",B29)-1) -> BMW | J29: =_xlfn.FORMULATEXT(I29) -> =LEFT(B29,FIND(" ",B29)-1)
B30: Audi A3 | C30: 2017 | D30: 130000 | E30: Red | F30: Manual | G30: 2nd owner | H30: $24321 | I30: =LEFT(B30,FIND(" ",B30)-1) -> Audi | J30: =_xlfn.FORMULATEXT(I30) -> =LEFT(B30,FIND(" ",B30)-1)
B31: Mercedes S-Class | C31: 2020 | D31: 92450 | E31: Black | F31: Automatic | G31: 3rd owner | H31: $102342 | I31: =LEFT(B31,FIND(" ",B31)-1) -> Mercedes | J31: =_xlfn.FORMULATEXT(I31) -> =LEFT(B31,FIND(" ",B31)-1)
B32: BMW X5 | C32: 2020 | D32: 76240 | E32: White | F32: Automatic | G32: 2nd owner | H32: $55272 | I32: =LEFT(B32,FIND(" ",B32)-1) -> BMW | J32: =_xlfn.FORMULATEXT(I32) -> =LEFT(B32,FIND(" ",B32)-1)
B33: BMW X3 | C33: 2021 | D33: 17283 | E33: White | F33: Manual | G33: 1st owner | H33: $42000 | I33: =LEFT(B33,FIND(" ",B33)-1) -> BMW | J33: =_xlfn.FORMULATEXT(I33) -> =LEFT(B33,FIND(" ",B33)-1)
B34: Lexus RX350 | C34: 2020 | D34: 98312 | E34: Red | F34: Automatic | G34: 3rd owner | H34: $51292 | I34: =LEFT(B34,FIND(" ",B34)-1) -> Lexus | J34: =_xlfn.FORMULATEXT(I34) -> =LEFT(B34,FIND(" ",B34)-1)
B35: BMW X3 | C35: 2018 | D35: 156784 | E35: Blue | F35: Manual | G35: 3rd owner | H35: $37605 | I35: =LEFT(B35,FIND(" ",B35)-1) -> BMW | J35: =_xlfn.FORMULATEXT(I35) -> =LEFT(B35,FIND(" ",B35)-1)
B36: BMW X5 | C36: 2019 | D36: 52034 | E36: Blue | F36: Automatic | G36: 1st owner | H36: $45000 | I36: =LEFT(B36,FIND(" ",B36)-1) -> BMW | J36: =_xlfn.FORMULATEXT(I36) -> =LEFT(B36,FIND(" ",B36)-1)
B37: BMW 3 Series | C37: 2011 | D37: 205204 | E37: Red | F37: Automatic | G37: 2nd owner | H37: $13241 | I37: =LEFT(B37,FIND(" ",B37)-1) -> BMW | J37: =_xlfn.FORMULATEXT(I37) -> =LEFT(B37,FIND(" ",B37)-1)
B38: Mercedes S-Class | C38: 2014 | D38: 152985 | E38: Black | F38: Automatic | G38: 2nd owner | H38: $49344 | I38: =LEFT(B38,FIND(" ",B38)-1) -> Mercedes | J38: =_xlfn.FORMULATEXT(I38) -> =LEFT(B38,FIND(" ",B38)-1)
B39: Tesla Model 3 | C39: 2018 | D39: 76429 | E39: Yellow | F39: Automatic | G39: 1st owner | H39: $52432 | I39: =LEFT(B39,FIND(" ",B39)-1) -> Tesla | J39: =_xlfn.FORMULATEXT(I39) -> =LEFT(B39,FIND(" ",B39)-1)
B40: Volvo XC90 | C40: 2013 | D40: 254028 | E40: Black | F40: Manual | G40: 2nd owner | H40: $17452 | I40: =LEFT(B40,FIND(" ",B40)-1) -> Volvo | J40: =_xlfn.FORMULATEXT(I40) -> =LEFT(B40,FIND(" ",B40)-1)
... B46: Lexus RX350 | C46: 2015 | D46: 130000 | E46: Black | F46: Automatic | G46: 4th owner | H46: $22520 | I46: =LEFT(B46,FIND(" ",B46)-1) -> Lexus | J46: =_xlfn.FORMULATEXT(I46) -> =LEFT(B46,FIND(" ",B46)-1)
B48: The LEFT function extracts characters from the left side of the cell. How many characters? This is determined in the 2nd argument here - And instead of writing a specific character position,
B49: we are using the FIND function to find the first space character position, and then subtract 1 (as we are not interested in extracting the space itself, only what's before.
B51: Click here to learn and practice the LEFT function
B52: Click here to learn and practice the FIND function
B54: Now that we have extracted the Manufacturer's name, we can check who's the most popular one:
B55: Let's use a UNIQUE & COUNTIF for this example:
B57: Manufacturer | C57: Count
...
