Workbook

Sheet Questions
B1: You were asked to assist your IT department with migrating information from the old employee system to the new system which was recently implemented.
B2: As the systems databases are different, some details in the new system are missing, and you're required to complete them, as much as possible.
B4: Fill the missing fields in the following worksheet, based on the instructions below:
B6: Email | C6: Employee ID | D6: First Name | E6: Last Name | F6: City | G6: Hire Date | H6: Experienced Employee? | I6: Payroll | J6: Payroll Raise %
B7: john.storm@gotrocks.net | C7: 9345 | D7: =PROPER(LEFT(B7, FIND(".",B7)-1)) -> John | E7: =PROPER(MID(B7, FIND(".",B7)+1, FIND("@",B7)-FIND(".",B7)-1)) -> Storm | F7: =_xlfn.XLOOKUP(B7,'Employee details - old system'!$A$2:$A$10,'Employee details - old system'!$C$2:$C$10, "London",0) -> London | G7: =_xlfn.XLOOKUP(B7,'Employee details - old system'!$A$2:$A$10,'Employee details - old system'!$B$2:$B$10, DATE(2020,1,5),0) -> 43835 | H7: =IF(YEAR(G7) < 2019, "Experienced", "Not Experienced") -> Not Experienced | I7: 10088 | J7: {=_xlfn.IFS(YEAR(G7)=2020,0.03,YEAR(G7)=2019,0.05,YEAR(G7)<=2018,0.1)} -> 0.03
B8: john.johnson@wahoo.com | C8: 6875 | D8: =PROPER(LEFT(B8, FIND(".",B8)-1)) -> John | E8: =PROPER(MID(B8, FIND(".",B8)+1, FIND("@",B8)-FIND(".",B8)-1)) -> Johnson | F8: =_xlfn.XLOOKUP(B8,'Employee details - old system'!$A$2:$A$10,'Employee details - old system'!$C$2:$C$10, "London",0) -> Manchester | G8: =_xlfn.XLOOKUP(B8,'Employee details - old system'!$A$2:$A$10,'Employee details - old system'!$B$2:$B$10, DATE(2020,1,5),0) -> 43484 | H8: =IF(YEAR(G8) < 2019, "Experienced", "Not Experienced") -> Not Experienced | I8: 11176 | J8: {=_xlfn.IFS(YEAR(G8)=2020,0.03,YEAR(G8)=2019,0.05,YEAR(G8)<=2018,0.1)} -> 0.05
B9: debby.powers@jeemail.com | C9: 6431 | D9: =PROPER(LEFT(B9, FIND(".",B9)-1)) -> Debby | E9: =PROPER(MID(B9, FIND(".",B9)+1, FIND("@",B9)-FIND(".",B9)-1)) -> Powers | F9: =_xlfn.XLOOKUP(B9,'Employee details - old system'!$A$2:$A$10,'Employee details - old system'!$C$2:$C$10, "London",0) -> Cardiff | G9: =_xlfn.XLOOKUP(B9,'Employee details - old system'!$A$2:$A$10,'Employee details - old system'!$B$2:$B$10, DATE(2020,1,5),0) -> 43364 | H9: =IF(YEAR(G9) < 2019, "Experienced", "Not Experienced") -> Experienced | I9: 10546 | J9: {=_xlfn.IFS(YEAR(G9)=2020,0.03,YEAR(G9)=2019,0.05,YEAR(G9)<=2018,0.1)} -> 0.1
B10: joe.byethen@whitehouse.gov | C10: 6076 | D10: =PROPER(LEFT(B10, FIND(".",B10)-1)) -> Joe | E10: =PROPER(MID(B10, FIND(".",B10)+1, FIND("@",B10)-FIND(".",B10)-1)) -> Byethen | F10: =_xlfn.XLOOKUP(B10,'Employee details - old system'!$A$2:$A$10,'Employee details - old system'!$C$2:$C$10, "London",0) -> Bristol | G10: =_xlfn.XLOOKUP(B10,'Employee details - old system'!$A$2:$A$10,'Employee details - old system'!$B$2:$B$10, DATE(2020,1,5),0) -> 43436 | H10: =IF(YEAR(G10) < 2019, "Experienced", "Not Experienced") -> Experienced | I10: 10004 | J10: {=_xlfn.IFS(YEAR(G10)=2020,0.03,YEAR(G10)=2019,0.05,YEAR(G10)<=2018,0.1)} -> 0.1
B11: stephanie.diaz@msm.org | C11: 8198 | D11: =PROPER(LEFT(B11, FIND(".",B11)-1)) -> Stephanie | E11: =PROPER(MID(B11, FIND(".",B11)+1, FIND("@",B11)-FIND(".",B11)-1)) -> Diaz | F11: =_xlfn.XLOOKUP(B11,'Employee details - old system'!$A$2:$A$10,'Employee details - old system'!$C$2:$C$10, "London",0) -> London | G11: =_xlfn.XLOOKUP(B11,'Employee details - old system'!$A$2:$A$10,'Employee details - old system'!$B$2:$B$10, DATE(2020,1,5),0) -> 43410 | H11: =IF(YEAR(G11) < 2019, "Experienced", "Not Experienced") -> Experienced | I11: 11383 | J11: {=_xlfn.IFS(YEAR(G11)=2020,0.03,YEAR(G11)=2019,0.05,YEAR(G11)<=2018,0.1)} -> 0.1
B12: donald.gump@wahoo.com | C12: 7220 | D12: =PROPER(LEFT(B12, FIND(".",B12)-1)) -> Donald | E12: =PROPER(MID(B12, FIND(".",B12)+1, FIND("@",B12)-FIND(".",B12)-1)) -> Gump | F12: =_xlfn.XLOOKUP(B12,'Employee details - old system'!$A$2:$A$10,'Employee details - old system'!$C$2:$C$10, "London",0) -> Liverpool | G12: =_xlfn.XLOOKUP(B12,'Employee details - old system'!$A$2:$A$10,'Employee details - old system'!$B$2:$B$10, DATE(2020,1,5),0) -> 43068 | H12: =IF(YEAR(G12) < 2019, "Experienced", "Not Experienced") -> Experienced | I12: 10236 | J12: {=_xlfn.IFS(YEAR(G12)=2020,0.03,YEAR(G12)=2019,0.05,YEAR(G12)<=2018,0.1)} -> 0.1
B13: sarah.cohen@coldmail.com | C13: 8638 | D13: =PROPER(LEFT(B13, FIND(".",B13)-1)) -> Sarah | E13: =PROPER(MID(B13, FIND(".",B13)+1, FIND("@",B13)-FIND(".",B13)-1)) -> Cohen | F13: =_xlfn.XLOOKUP(B13,'Employee details - old system'!$A$2:$A$10,'Employee details - old system'!$C$2:$C$10, "London",0) -> Birmingham | G13: =_xlfn.XLOOKUP(B13,'Employee details - old system'!$A$2:$A$10,'Employee details - old system'!$B$2:$B$10, DATE(2020,1,5),0) -> 43420 | H13: =IF(YEAR(G13) < 2019, "Experienced", "Not Experienced") -> Experienced | I13: 10822 | J13: {=_xlfn.IFS(YEAR(G13)=2020,0.03,YEAR(G13)=2019,0.05,YEAR(G13)<=2018,0.1)} -> 0.1
B14: vladimir.lupin@kremlinmail.com | C14: 8187 | D14: =PROPER(LEFT(B14, FIND(".",B14)-1)) -> Vladimir | E14: =PROPER(MID(B14, FIND(".",B14)+1, FIND("@",B14)-FIND(".",B14)-1)) -> Lupin | F14: =_xlfn.XLOOKUP(B14,'Employee details - old system'!$A$2:$A$10,'Employee details - old system'!$C$2:$C$10, "London",0) -> Cambridge | G14: =_xlfn.XLOOKUP(B14,'Employee details - old system'!$A$2:$A$10,'Employee details - old system'!$B$2:$B$10, DATE(2020,1,5),0) -> 43438 | H14: =IF(YEAR(G14) < 2019, "Experienced", "Not Experienced") -> Experienced | I14: 11379 | J14: {=_xlfn.IFS(YEAR(G14)=2020,0.03,YEAR(G14)=2019,0.05,YEAR(G14)<=2018,0.1)} -> 0.1
A16: A | B16: Extract the First and Last Name of each employee based on the email address, which is in the following format:
B17: firstname.lastname@emailprovider.com
B18: firstname - Employee's First Name
B19: lastname - Employee's Last Name
A21: B | B21: Retrieve the cities where each employee lives from the old system. In case a certain employee isn't found in the old database, it means that he's a new hire, and therefore the default is London.
A22: C | B22: Retrieve the hire date of the employees. In case the hire date is missing, it means that the employee was hired on January 5, 2020.
A23: D | B23: If an employee was hired before 2019, it means he's an experienced employee. Otherwise, return "No experience"
A24: E | B24: Your company had outstanding financial results in 2020, so the CEO decided to raise the payroll of all the employees in the company, in the following rates:
B25: Employees hired in 2020 - 3% Raise
B26: Employees hired in 2019 - 5% Raise
B27: Employees hired in 2018 or before - 10% Raise
B29: Fill the percentages in the "Payroll Raise %" column accordingly.
B31: Good Luck!

Sheet Employee details - old system
A1: Email | B1: Hire date | C1: City
A2: john.johnson@wahoo.com | B2: 43484 | C2: Manchester
A3: debby.powers@jeemail.com | B3: 43364 | C3: Cardiff
A4: sarah.cohen@coldmail.com | B4: 43420 | C4: Birmingham
A5: liza.olson@owl.com | B5: 43045 | C5: Liverpool
A6: stephanie.diaz@msm.org | B6: 43410 | C6: London
A7: donald.gump@wahoo.com | B7: 43068 | C7: Liverpool
A8: joe.byethen@whitehouse.gov | B8: 43436 | C8: Bristol
A9: barrack.ohara@jeemail.com | B9: 43354 | C9: Belfast
A10: vladimir.lupin@kremlinmail.com | B10: 43438 | C10: Cambridge

Sheet Solution
B1: Email | C1: Employee ID | D1: First Name | E1: Last Name | F1: City | G1: Hire Date | H1: Experienced Employee? | I1: Payroll | J1: Payroll Raise %
B2: john.storm@gotrocks.net | C2: 9345 | D2: =PROPER(LEFT(B2,FIND(".",B2)-1)) -> John | E2: =PROPER(MID(B2,FIND(".",B2)+1,FIND("@",B2)-FIND(".",B2)-1)) -> Storm | F2: =IFERROR(VLOOKUP(B2,'Employee details - old system'!$A$1:$C$10,3,0),"London") -> London | G2: =IFERROR(VLOOKUP(B2,'Employee details - old system'!$A$1:$B$10,2,0),DATE(2020,5,1)) -> 43952 | H2: =IF(YEAR(G2)<2019,"Experienced","No Experience") -> No Experience | I2: 10088 | J2: =IF(YEAR(G2)<=2018,10%,IF(YEAR(G2)=2019,5%,3%)) -> 0.03
B3: john.johnson@wahoo.com | C3: 6875 | D3: =PROPER(LEFT(B3,FIND(".",B3)-1)) -> John | E3: =PROPER(MID(B3,FIND(".",B3)+1,FIND("@",B3)-FIND(".",B3)-1)) -> Johnson | F3: =IFERROR(VLOOKUP(B3,'Employee details - old system'!$A$1:$C$10,3,0),"London") -> Manchester | G3: =IFERROR(VLOOKUP(B3,'Employee details - old system'!$A$1:$B$10,2,0),"01/05/2020") -> 43484 | H3: =IF(YEAR(G3)<2019,"Experienced","No Experience") -> No Experience | I3: 11176 | J3: =IF(YEAR(G3)<=2018,10%,IF(YEAR(G3)=2019,5%,3%)) -> 0.05
B4: debby.powers@jeemail.com | C4: 6431 | D4: =PROPER(LEFT(B4,FIND(".",B4)-1)) -> Debby | E4: =PROPER(MID(B4,FIND(".",B4)+1,FIND("@",B4)-FIND(".",B4)-1)) -> Powers | F4: =IFERROR(VLOOKUP(B4,'Employee details - old system'!$A$1:$C$10,3,0),"London") -> Cardiff | G4: =IFERROR(VLOOKUP(B4,'Employee details - old system'!$A$1:$B$10,2,0),"01/05/2020") -> 43364 | H4: =IF(YEAR(G4)<2019,"Experienced","No Experience") -> Experienced | I4: 10546 | J4: =IF(YEAR(G4)<=2018,10%,IF(YEAR(G4)=2019,5%,3%)) -> 0.1
B5: joe.byethen@whitehouse.gov | C5: 6076 | D5: =PROPER(LEFT(B5,FIND(".",B5)-1)) -> Joe | E5: =PROPER(MID(B5,FIND(".",B5)+1,FIND("@",B5)-FIND(".",B5)-1)) -> Byethen | F5: =IFERROR(VLOOKUP(B5,'Employee details - old system'!$A$1:$C$10,3,0),"London") -> Bristol | G5: =IFERROR(VLOOKUP(B5,'Employee details - old system'!$A$1:$B$10,2,0),"01/05/2020") -> 43436 | H5: =IF(YEAR(G5)<2019,"Experienced","No Experience") -> Experienced | I5: 10004 | J5: =IF(YEAR(G5)<=2018,10%,IF(YEAR(G5)=2019,5%,3%)) -> 0.1
B6: stephanie.diaz@msm.org | C6: 8198 | D6: =PROPER(LEFT(B6,FIND(".",B6)-1)) -> Stephanie | E6: =PROPER(MID(B6,FIND(".",B6)+1,FIND("@",B6)-FIND(".",B6)-1)) -> Diaz | F6: =IFERROR(VLOOKUP(B6,'Employee details - old system'!$A$1:$C$10,3,0),"London") -> London | G6: =IFERROR(VLOOKUP(B6,'Employee details - old system'!$A$1:$B$10,2,0),"01/05/2020") -> 43410 | H6: =IF(YEAR(G6)<2019,"Experienced","No Experience") -> Experienced | I6: 11383 | J6: =IF(YEAR(G6)<=2018,10%,IF(YEAR(G6)=2019,5%,3%)) -> 0.1
B7: donald.gump@wahoo.com | C7: 7220 | D7: =PROPER(LEFT(B7,FIND(".",B7)-1)) -> Donald | E7: =PROPER(MID(B7,FIND(".",B7)+1,FIND("@",B7)-FIND(".",B7)-1)) -> Gump | F7: =IFERROR(VLOOKUP(B7,'Employee details - old system'!$A$1:$C$10,3,0),"London") -> Liverpool | G7: =IFERROR(VLOOKUP(B7,'Employee details - old system'!$A$1:$B$10,2,0),"01/05/2020") -> 43068 | H7: =IF(YEAR(G7)<2019,"Experienced","No Experience") -> Experienced | I7: 10236 | J7: =IF(YEAR(G7)<=2018,10%,IF(YEAR(G7)=2019,5%,3%)) -> 0.1
B8: sarah.cohen@coldmail.com | C8: 8638 | D8: =PROPER(LEFT(B8,FIND(".",B8)-1)) -> Sarah | E8: =PROPER(MID(B8,FIND(".",B8)+1,FIND("@",B8)-FIND(".",B8)-1)) -> Cohen | F8: =IFERROR(VLOOKUP(B8,'Employee details - old system'!$A$1:$C$10,3,0),"London") -> Birmingham | G8: =IFERROR(VLOOKUP(B8,'Employee details - old system'!$A$1:$B$10,2,0),"01/05/2020") -> 43420 | H8: =IF(YEAR(G8)<2019,"Experienced","No Experience") -> Experienced | I8: 10822 | J8: =IF(YEAR(G8)<=2018,10%,IF(YEAR(G8)=2019,5%,3%)) -> 0.1
B9: vladimir.lupin@kremlinmail.com | C9: 8187 | D9: =PROPER(LEFT(B9,FIND(".",B9)-1)) -> Vladimir | E9: =PROPER(MID(B9,FIND(".",B9)+1,FIND("@",B9)-FIND(".",B9)-1)) -> Lupin | F9: =IFERROR(VLOOKUP(B9,'Employee details - old system'!$A$1:$C$10,3,0),"London") -> Cambridge | G9: =IFERROR(VLOOKUP(B9,'Employee details - old system'!$A$1:$B$10,2,0),"01/05/2020") -> 43438 | H9: =IF(YEAR(G9)<2019,"Experienced","No Experience") -> Experienced | I9: 11379 | J9: =IF(YEAR(G9)<=2018,10%,IF(YEAR(G9)=2019,5%,3%)) -> 0.1
B11: For our example, we'll see how we solved the question for John Storm - the first row in the table.
A12: A | B12: To extract the first and last name, we can use the Left, Find & Mid functions.
B13: Let's start with the first name:
B14: =_xlfn.FORMULATEXT(D2) -> =PROPER(LEFT(B2,FIND(".",B2)-1))
B16: LEFT Syntax:
B17: =LEFT("text",num_chars)
B19: We use the LEFT function to extract the first characters from the text.
B20: How many characters exactly? This will be determined within the num_chars argument.
B22: As we know that the first name ends when the dot (.) appears, we can ask Excel to find the position of that dot and the number of characters will be the position minus 1 (as the dot itself is irrelevant)
B23: We will use the FIND function for that.
B25: Find Syntax:
B26: =FIND(find_text,within_text,[start_num])
B28: find_text | C28: What we are looking for? In our example - the dot (.) sign
B29: within_text | C29: Where are we looking for it? In our example - Cell B2 which contains John Storm's email address.
B30: [start_num] | C30: This is an optional argument, which is not required here as we are looking to start the search from the start of the cell.
B32: After we found the location of the dot (.) using FIND, we will subtract 1 (minus 1), because we don't want to extract the dot - we want to stop one character before it.
B34: BONUS - we can use the PROPER function to capitalize the first letter of the name.
B36: Now, let's see how to extract the last name:
B37: =_xlfn.FORMULATEXT(E2) -> =PROPER(MID(B2,FIND(".",B2)+1,FIND("@",B2)-FIND(".",B2)-1))
B39: This one is a bit trickier :)
B40: First, to extract the characters from the middle of a cell, we can use the MID formula.
B41: The MID formula syntax is as follows:
B42: =MID(text, start_num, num_chars)
B43: text - From which text we want to extract the characters?
B44: start_num - What is the position of the first character to be extracted?
B45: num_chars - Starting from the position noted in start_num, how many characters to extract?
B47: start_num - FIND(".",B2)+1
B48: We know that the last name starts after the dot. So we'll use the FIND formula to find the position of the dot.
B49: We will add + 1, as we do not want to extract the dot itself, but only what comes afterwards.
B51: num_chars - FIND("@",B2)-FIND(".",B2)-1
B52: We will try to calculate the length of the last name by first finding where it ends - it ends with the @ sign. Then we find where it starts - we know it's the dot sign.
...
